Workbook

Sheet Portfolio  Holdings
B2: MF + ETF PORTFOLIO XIRR | D2: =C293 -> 0.19157735 | F2: NIFTY Return in the same period: | G2: =(F7/F6)^(1/F8) - 1 -> 0.1713798
B3: DATES | C3: AMOUNT | D3: Cum Sum
B4: 44126 | C4: -100 | D4: =IFERROR(__xludf.DUMMYFUNCTION("-(SUM($C$4:C4))"),100) -> 100 | E4: =B4 -> 44126 | F4: =E4 -> 44126
B5: 44126 | C5: -499 | D5: =IFERROR(__xludf.DUMMYFUNCTION("-(SUM($C$4:C5))"),599) -> 599 | E5: =B5 -> 44126 | F5: =TODAY()-1 -> 45861
B6: 44126 | C6: -499 | D6: =IFERROR(__xludf.DUMMYFUNCTION("-(SUM($C$4:C6))"),1098) -> 1098 | E6: =B6 -> 44126 | F6: =IFERROR(__xludf.DUMMYFUNCTION("INDEX(GOOGLEFINANCE(""NIFTY_50"", ""price"", F4), 2, 2)"),11896.45) -> 11896.45
B7: 44152 | C7: 101 | D7: =IFERROR(__xludf.DUMMYFUNCTION("-(SUM($C$4:C7))"),997) -> 997 | E7: =B7 -> 44152 | F7: =IFERROR(__xludf.DUMMYFUNCTION("INDEX(GOOGLEFINANCE(""NIFTY_50"", ""price"", F5), 2, 2)"),25219.9) -> 25219.9
B8: 44162 | C8: 495 | D8: =IFERROR(__xludf.DUMMYFUNCTION("-(SUM($C$4:C8))"),502) -> 502 | E8: =B8 -> 44162 | F8: =(F5-F4)/365.25 -> 4.7501711
B9: 44169 | C9: -499 | D9: =IFERROR(__xludf.DUMMYFUNCTION("-(SUM($C$4:C9))"),1001) -> 1001 | E9: =B9 -> 44169
B10: 44180 | C10: -499 | D10: =IFERROR(__xludf.DUMMYFUNCTION("-(SUM($C$4:C10))"),1500) -> 1500 | E10: =B10 -> 44180
B11: 44181 | C11: -499 | D11: =IFERROR(__xludf.DUMMYFUNCTION("-(SUM($C$4:C11))"),1999) -> 1999 | E11: =B11 -> 44181
B12: 44208 | C12: -999 | D12: =IFERROR(__xludf.DUMMYFUNCTION("-(SUM($C$4:C12))"),2998) -> 2998 | E12: =B12 -> 44208 | G12: Mutual Fund
B13: 44211 | C13: -499 | D13: =IFERROR(__xludf.DUMMYFUNCTION("-(SUM($C$4:C13))"),3497) -> 3497 | E13: =B13 -> 44211
B14: 44242 | C14: -499 | D14: =IFERROR(__xludf.DUMMYFUNCTION("-(SUM($C$4:C14))"),3996) -> 3996 | E14: =B14 -> 44242 | G14: Invested Value | H14: Profit | I14: Today
B15: 44242 | C15: -995 | D15: =IFERROR(__xludf.DUMMYFUNCTION("-(SUM($C$4:C15))"),4991) -> 4991 | E15: =B15 -> 44242 | G15: ='MF holdings and transactions'!A291 -> 98528 | H15: ='MF holdings and transactions'!B291 -> 36209 | I15: ='MF holdings and transactions'!C291 -> 60968.396
B16: 44242 | C16: 995 | D16: =IFERROR(__xludf.DUMMYFUNCTION("-(SUM($C$4:C16))"),3996) -> 3996 | E16: =B16 -> 44242
B17: 44242 | C17: -499 | D17: =IFERROR(__xludf.DUMMYFUNCTION("-(SUM($C$4:C17))"),4495) -> 4495 | E17: =B17 -> 44242 | G17: ETF
B18: 44270 | C18: -499 | D18: =IFERROR(__xludf.DUMMYFUNCTION("-(SUM($C$4:C18))"),4994) -> 4994 | E18: =B18 -> 44270
B19: 44270 | C19: -499 | D19: =IFERROR(__xludf.DUMMYFUNCTION("-(SUM($C$4:C19))"),5493) -> 5493 | E19: =B19 -> 44270 | G19: Invested Value | H19: Profit | I19: Today
B20: 44301 | C20: -499 | D20: =IFERROR(__xludf.DUMMYFUNCTION("-(SUM($C$4:C20))"),5992) -> 5992 | E20: =B20 -> 44301 | G20: ='Stocks Transaction'!I50 -> 25362.63 | H20: ='Stocks Transaction'!J50 -> 9296 | I20: ='Stocks Transaction'!K50 -> 23447.97
B21: 44301 | C21: -499 | D21: =IFERROR(__xludf.DUMMYFUNCTION("-(SUM($C$4:C21))"),6491) -> 6491 | E21: =B21 -> 44301 | J21: Profit + Today
B22: 44333 | C22: -499 | D22: =IFERROR(__xludf.DUMMYFUNCTION("-(SUM($C$4:C22))"),6990) -> 6990 | E22: =B22 -> 44333 | F22: TOTAL | G22: =G15+G20 -> 123890.63 | H22: =H15+H20 -> 45505 | I22: =I15+I20 -> 84416.366 | J22: =H22+I22 -> 129921.37
B23: 44333 | C23: -499 | D23: =IFERROR(__xludf.DUMMYFUNCTION("-(SUM($C$4:C23))"),7489) -> 7489 | E23: =B23 -> 44333 | I23: ABS RETURN | J23: =G22/J22 -> 0.95358165
B24: 44362 | C24: -499 | D24: =IFERROR(__xludf.DUMMYFUNCTION("-(SUM($C$4:C24))"),7988) -> 7988 | E24: =B24 -> 44362
B25: 44362 | C25: -499 | D25: =IFERROR(__xludf.DUMMYFUNCTION("-(SUM($C$4:C25))"),8487) -> 8487 | E25: =B25 -> 44362
B26: 44376 | C26: -3830 | D26: =IFERROR(__xludf.DUMMYFUNCTION("-(SUM($C$4:C26))"),12317) -> 12317 | E26: =B26 -> 44376
B27: 44376 | C27: 3830 | D27: =IFERROR(__xludf.DUMMYFUNCTION("-(SUM($C$4:C27))"),8487) -> 8487 | E27: =B27 -> 44376
B28: 44392 | C28: -499 | D28: =IFERROR(__xludf.DUMMYFUNCTION("-(SUM($C$4:C28))"),8986) -> 8986 | E28: =B28 -> 44392
B29: 44393 | C29: 1009 | D29: =IFERROR(__xludf.DUMMYFUNCTION("-(SUM($C$4:C29))"),7977) -> 7977 | E29: =B29 -> 44393
B30: 44393 | C30: -1009 | D30: =IFERROR(__xludf.DUMMYFUNCTION("-(SUM($C$4:C30))"),8986) -> 8986 | E30: =B30 -> 44393
B31: 44393 | C31: -499 | D31: =IFERROR(__xludf.DUMMYFUNCTION("-(SUM($C$4:C31))"),9485) -> 9485 | E31: =B31 -> 44393
B32: 44393 | C32: -499 | D32: =IFERROR(__xludf.DUMMYFUNCTION("-(SUM($C$4:C32))"),9984) -> 9984 | E32: =B32 -> 44393
B33: 44393 | C33: -499 | D33: =IFERROR(__xludf.DUMMYFUNCTION("-(SUM($C$4:C33))"),10483) -> 10483 | E33: =B33 -> 44393
B34: 44420 | C34: -199 | D34: =IFERROR(__xludf.DUMMYFUNCTION("-(SUM($C$4:C34))"),10682) -> 10682 | E34: =B34 -> 44420
B35: 44424 | C35: -499 | D35: =IFERROR(__xludf.DUMMYFUNCTION("-(SUM($C$4:C35))"),11181) -> 11181 | E35: =B35 -> 44424
B36: 44424 | C36: -499 | D36: =IFERROR(__xludf.DUMMYFUNCTION("-(SUM($C$4:C36))"),11680) -> 11680 | E36: =B36 -> 44424
B37: 44424 | C37: -499 | D37: =IFERROR(__xludf.DUMMYFUNCTION("-(SUM($C$4:C37))"),12179) -> 12179 | E37: =B37 -> 44424
B38: 44454 | C38: -199 | D38: =IFERROR(__xludf.DUMMYFUNCTION("-(SUM($C$4:C38))"),12378) -> 12378 | E38: =B38 -> 44454
B39: 44454 | C39: -499 | D39: =IFERROR(__xludf.DUMMYFUNCTION("-(SUM($C$4:C39))"),12877) -> 12877 | E39: =B39 -> 44454
B40: 44454 | C40: -499 | D40: =IFERROR(__xludf.DUMMYFUNCTION("-(SUM($C$4:C40))"),13376) -> 13376 | E40: =B40 -> 44454
B41: 44454 | C41: -499 | D41: =IFERROR(__xludf.DUMMYFUNCTION("-(SUM($C$4:C41))"),13875) -> 13875 | E41: =B41 -> 44454
...

Sheet MF holdings and transactions
A3: Personal Details
A4: Name
A5: Mobile Number
A6: PAN
B9: DATE
A10: TRANSACTIONS TILL | B10: =TODAY() -> 45862
P11: XIRR (WITHOUT SWITCH)
A12: Scheme Name | B12: Transaction Type | C12: Units | D12: NAV | E12: Amount | F12: Date | G12: Amount in/out | H12: ="2000 SIP Going (" & IF(DAY(TODAY()) > 17, DATEDIF(DATE(2024, 1, 1), TODAY(), "M") + 1, DATEDIF(DATE(2024, 1, 1), TODAY(), "M")) & ")" -> 2000 SIP Going (19) | P12: DATES | Q12: AMOUNT
A14: UTI Nifty200 Momentum 30 Index Fund Direct Growth | B14: PURCHASE | C14: 23.18 | D14: 21.57 | E14: 499 | F14: 45853 | G14: =IFERROR(__xludf.DUMMYFUNCTION("IF(E14="""", """", IF(OR(B14=""PURCHASE"", B14=""SWITCH PURCHASE""), E14*-1, E14)) "),-499) -> -499 | P14: 45853 | Q14: -499
A15: Nippon India Nifty Midcap 150 Index Fund Direct Growth | B15: PURCHASE | C15: 19.73 | D15: 25.35 | E15: 499 | F15: 45853 | G15: =IFERROR(__xludf.DUMMYFUNCTION("IF(E15="""", """", IF(OR(B15=""PURCHASE"", B15=""SWITCH PURCHASE""), E15*-1, E15)) "),-499) -> -499 | P15: 45853 | Q15: -499
A16: HDFC Short Term Debt Fund Direct Plan Growth | B16: PURCHASE | C16: 15.02 | D16: 33.29 | E16: 499 | F16: 45853 | G16: =IFERROR(__xludf.DUMMYFUNCTION("IF(E16="""", """", IF(OR(B16=""PURCHASE"", B16=""SWITCH PURCHASE""), E16*-1, E16)) "),-499) -> -499 | P16: 45853 | Q16: -499
A17: UTI Nifty200 Momentum 30 Index Fund Direct Growth | B17: PURCHASE | C17: 23 | D17: 21.74 | E17: 499 | F17: 45824 | G17: =IFERROR(__xludf.DUMMYFUNCTION("IF(E17="""", """", IF(OR(B17=""PURCHASE"", B17=""SWITCH PURCHASE""), E17*-1, E17)) "),-499) -> -499 | P17: 45824 | Q17: -499
A18: Nippon India Nifty Midcap 150 Index Fund Direct Growth | B18: PURCHASE | C18: 20.08 | D18: 24.9 | E18: 499 | F18: 45824 | G18: =IFERROR(__xludf.DUMMYFUNCTION("IF(E18="""", """", IF(OR(B18=""PURCHASE"", B18=""SWITCH PURCHASE""), E18*-1, E18)) "),-499) -> -499 | P18: 45824 | Q18: -499
A19: HDFC Short Term Debt Fund Direct Plan Growth | B19: PURCHASE | C19: 15.11 | D19: 33.09 | E19: 499 | F19: 45824 | G19: =IFERROR(__xludf.DUMMYFUNCTION("IF(E19="""", """", IF(OR(B19=""PURCHASE"", B19=""SWITCH PURCHASE""), E19*-1, E19)) "),-499) -> -499 | P19: 45824 | Q19: -499
A20: HDFC Short Term Debt Fund Direct Plan Growth | B20: REDEEM | C20: 30.57 | D20: 33.18 | E20: 1014 | F20: 45817 | G20: =IFERROR(__xludf.DUMMYFUNCTION("IF(E20="""", """", IF(OR(B20=""PURCHASE"", B20=""SWITCH PURCHASE""), E20*-1, E20)) "),1014) -> 1014 | P20: 45817 | Q20: 1014
A21: HDFC Short Term Debt Fund Direct Plan Growth | B21: PURCHASE | C21: 15.21 | D21: 32.88 | E21: 499 | F21: 45792 | G21: =IFERROR(__xludf.DUMMYFUNCTION("IF(E21="""", """", IF(OR(B21=""PURCHASE"", B21=""SWITCH PURCHASE""), E21*-1, E21)) "),-499) -> -499 | P21: 45792 | Q21: -499
A22: UTI Nifty200 Momentum 30 Index Fund Direct Growth | B22: PURCHASE | C22: 23.59 | D22: 21.19 | E22: 499 | F22: 45792 | G22: =IFERROR(__xludf.DUMMYFUNCTION("IF(E22="""", """", IF(OR(B22=""PURCHASE"", B22=""SWITCH PURCHASE""), E22*-1, E22)) "),-499) -> -499 | P22: 45792 | Q22: -499
A23: Nippon India Nifty Midcap 150 Index Fund Direct Growth | B23: PURCHASE | C23: 20.87 | D23: 23.96 | E23: 499 | F23: 45792 | G23: =IFERROR(__xludf.DUMMYFUNCTION("IF(E23="""", """", IF(OR(B23=""PURCHASE"", B23=""SWITCH PURCHASE""), E23*-1, E23)) "),-499) -> -499 | P23: 45792 | Q23: -499
A24: HDFC Short Term Debt Fund Direct Plan Growth | B24: PURCHASE | C24: 15.36 | D24: 32.55 | E24: 499 | F24: 45762 | G24: =IFERROR(__xludf.DUMMYFUNCTION("IF(E24="""", """", IF(OR(B24=""PURCHASE"", B24=""SWITCH PURCHASE""), E24*-1, E24)) "),-499) -> -499 | P24: 45762 | Q24: -499
A25: Nippon India Nifty Midcap 150 Index Fund Direct Growth | B25: PURCHASE | C25: 22.61 | D25: 22.12 | E25: 499 | F25: 45762 | G25: =IFERROR(__xludf.DUMMYFUNCTION("IF(E25="""", """", IF(OR(B25=""PURCHASE"", B25=""SWITCH PURCHASE""), E25*-1, E25)) "),-499) -> -499 | P25: 45762 | Q25: -499
A26: UTI Nifty200 Momentum 30 Index Fund Direct Growth | B26: PURCHASE | C26: 26.19 | D26: 19.09 | E26: 499 | F26: 45762 | G26: =IFERROR(__xludf.DUMMYFUNCTION("IF(E26="""", """", IF(OR(B26=""PURCHASE"", B26=""SWITCH PURCHASE""), E26*-1, E26)) "),-499) -> -499 | P26: 45762 | Q26: -499
A27: HDFC Short Term Debt Fund Direct Plan Growth | B27: PURCHASE | C27: 15.62 | D27: 32.01 | E27: 499 | F27: 45733 | G27: =IFERROR(__xludf.DUMMYFUNCTION("IF(E27="""", """", IF(OR(B27=""PURCHASE"", B27=""SWITCH PURCHASE""), E27*-1, E27)) "),-499) -> -499 | P27: 45733 | Q27: -499
A28: UTI Nifty200 Momentum 30 Index Fund Direct Growth | B28: PURCHASE | C28: 26.92 | D28: 18.57 | E28: 499 | F28: 45733 | G28: =IFERROR(__xludf.DUMMYFUNCTION("IF(E28="""", """", IF(OR(B28=""PURCHASE"", B28=""SWITCH PURCHASE""), E28*-1, E28)) "),-499) -> -499 | P28: 45733 | Q28: -499
A29: Nippon India Nifty Midcap 150 Index Fund Direct Growth | B29: PURCHASE | C29: 24.02 | D29: 20.81 | E29: 499 | F29: 45733 | G29: =IFERROR(__xludf.DUMMYFUNCTION("IF(E29="""", """", IF(OR(B29=""PURCHASE"", B29=""SWITCH PURCHASE""), E29*-1, E29)) "),-499) -> -499 | P29: 45733 | Q29: -499
A30: Nippon India Nifty Midcap 150 Index Fund Direct Growth | B30: PURCHASE | C30: 24.02 | D30: 20.81 | E30: 499 | F30: 45733 | G30: =IFERROR(__xludf.DUMMYFUNCTION("IF(E30="""", """", IF(OR(B30=""PURCHASE"", B30=""SWITCH PURCHASE""), E30*-1, E30)) "),-499) -> -499 | P30: 45733 | Q30: -499
A31: UTI Nifty200 Momentum 30 Index Fund Direct Growth | B31: PURCHASE | C31: 25.61 | D31: 19.52 | E31: 499 | F31: 45705 | G31: =IFERROR(__xludf.DUMMYFUNCTION("IF(E31="""", """", IF(OR(B31=""PURCHASE"", B31=""SWITCH PURCHASE""), E31*-1, E31)) "),-499) -> -499 | P31: 45705 | Q31: -499
A32: Nippon India Nifty Midcap 150 Index Fund Direct Growth | B32: PURCHASE | C32: 23.53 | D32: 21.25 | E32: 499 | F32: 45705 | G32: =IFERROR(__xludf.DUMMYFUNCTION("IF(E32="""", """", IF(OR(B32=""PURCHASE"", B32=""SWITCH PURCHASE""), E32*-1, E32)) "),-499) -> -499 | P32: 45705 | Q32: -499
A33: HDFC Short Term Debt Fund Direct Plan Growth | B33: PURCHASE | C33: 15.69 | D33: 31.87 | E33: 499 | F33: 45705 | G33: =IFERROR(__xludf.DUMMYFUNCTION("IF(E33="""", """", IF(OR(B33=""PURCHASE"", B33=""SWITCH PURCHASE""), E33*-1, E33)) "),-499) -> -499 | P33: 45705 | Q33: -499
A34: Nippon India Nifty Midcap 150 Index Fund Direct Growth | B34: PURCHASE | C34: 23.53 | D34: 21.25 | E34: 499 | F34: 45705 | G34: =IFERROR(__xludf.DUMMYFUNCTION("IF(E34="""", """", IF(OR(B34=""PURCHASE"", B34=""SWITCH PURCHASE""), E34*-1, E34)) "),-499) -> -499 | P34: 45705 | Q34: -499
A35: Nippon India Nifty Midcap 150 Index Fund Direct Growth | B35: PURCHASE | C35: 21.48 | D35: 23.28 | E35: 499 | F35: 45674 | G35: =IFERROR(__xludf.DUMMYFUNCTION("IF(E35="""", """", IF(OR(B35=""PURCHASE"", B35=""SWITCH PURCHASE""), E35*-1, E35)) "),-499) -> -499 | P35: 45674 | Q35: -499
A36: UTI Nifty200 Momentum 30 Index Fund Direct Growth | B36: PURCHASE | C36: 23.59 | D36: 21.19 | E36: 499 | F36: 45672 | G36: =IFERROR(__xludf.DUMMYFUNCTION("IF(E36="""", """", IF(OR(B36=""PURCHASE"", B36=""SWITCH PURCHASE""), E36*-1, E36)) "),-499) -> -499 | P36: 45672 | Q36: -499
A37: Nippon India Nifty Midcap 150 Index Fund Direct Growth | B37: PURCHASE | C37: 21.73 | D37: 23 | E37: 499 | F37: 45672 | G37: =IFERROR(__xludf.DUMMYFUNCTION("IF(E37="""", """", IF(OR(B37=""PURCHASE"", B37=""SWITCH PURCHASE""), E37*-1, E37)) "),-499) -> -499 | P37: 45672 | Q37: -499
A38: HDFC Short Term Debt Fund Direct Plan Growth | B38: PURCHASE | C38: 15.82 | D38: 31.6 | E38: 499 | F38: 45672 | G38: =IFERROR(__xludf.DUMMYFUNCTION("IF(E38="""", """", IF(OR(B38=""PURCHASE"", B38=""SWITCH PURCHASE""), E38*-1, E38)) "),-499) -> -499 | P38: 45672 | Q38: -499
A39: HDFC Short Term Debt Fund Direct Plan Growth | B39: PURCHASE | C39: 15.88 | D39: 31.49 | E39: 499 | F39: 45642 | G39: =IFERROR(__xludf.DUMMYFUNCTION("IF(E39="""", """", IF(OR(B39=""PURCHASE"", B39=""SWITCH PURCHASE""), E39*-1, E39)) "),-499) -> -499 | P39: 45642 | Q39: -499
A40: UTI Nifty200 Momentum 30 Index Fund Direct Growth | B40: PURCHASE | C40: 20.49 | D40: 24.4 | E40: 499 | F40: 45642 | G40: =IFERROR(__xludf.DUMMYFUNCTION("IF(E40="""", """", IF(OR(B40=""PURCHASE"", B40=""SWITCH PURCHASE""), E40*-1, E40)) "),-499) -> -499 | P40: 45642 | Q40: -499
A41: MOTILAL OSWAL NASDAQ 100 FUND OF FUND - DIRECT GROWTH | B41: PURCHASE | C41: 11.33 | D41: 44.13 | E41: 499 | F41: 45642 | G41: =IFERROR(__xludf.DUMMYFUNCTION("IF(E41="""", """", IF(OR(B41=""PURCHASE"", B41=""SWITCH PURCHASE""), E41*-1, E41)) "),-499) -> -499 | P41: 45642 | Q41: -499
A42: Nippon India Nifty Midcap 150 Index Fund Direct Growth | B42: PURCHASE | C42: 19.81 | D42: 25.24 | E42: 499 | F42: 45642 | G42: =IFERROR(__xludf.DUMMYFUNCTION("IF(E42="""", """", IF(OR(B42=""PURCHASE"", B42=""SWITCH PURCHASE""), E42*-1, E42)) "),-499) -> -499 | P42: 45642 | Q42: -499
A43: UTI Nifty200 Momentum 30 Index Fund Direct Growth | B43: PURCHASE | C43: 22.05 | D43: 22.67 | E43: 499 | F43: 45614 | G43: =IFERROR(__xludf.DUMMYFUNCTION("IF(E43="""", """", IF(OR(B43=""PURCHASE"", B43=""SWITCH PURCHASE""), E43*-1, E43)) "),-499) -> -499 | P43: 45614 | Q43: -499
A44: MOTILAL OSWAL NASDAQ 100 FUND OF FUND - DIRECT GROWTH | B44: PURCHASE | C44: 13.88 | D44: 36.04 | E44: 499 | F44: 45614 | G44: =IFERROR(__xludf.DUMMYFUNCTION("IF(E44="""", """", IF(OR(B44=""PURCHASE"", B44=""SWITCH PURCHASE""), E44*-1, E44)) "),-499) -> -499 | P44: 45614 | Q44: -499
A45: Nippon India Nifty Midcap 150 Index Fund Direct Growth | B45: PURCHASE | C45: 21.61 | D45: 23.14 | E45: 499 | F45: 45614 | G45: =IFERROR(__xludf.DUMMYFUNCTION("IF(E45="""", """", IF(OR(B45=""PURCHASE"", B45=""SWITCH PURCHASE""), E45*-1, E45)) "),-499) -> -499 | P45: 45614 | Q45: -499
...

Sheet MF CAS
A1: ICICI Prudential Technology Fund - Direct - Growth
A3: Scheme Name | B3: Transaction Type | C3: Units | D3: NAV | E3: Amount | F3: Date | G3: Amount in/out
A4: ICICI Prudential Technology Fund - Direct - Growth | B4: REDEEM | C4: 1.1 | D4: 91.63 | E4: 101 | F4: 44152 | G4: 101
A5: ICICI Prudential Technology Fund - Direct - Growth | B5: PURCHASE | C5: 1.1 | D5: 90.46 | E5: 100 | F5: 44126 | G5: -100
A6: TOTAL | C6: 0
F7: XIRR | G7: 0.14991421
A8: Tata Liquid Fund Direct Growth
A10: Scheme Name | B10: Transaction Type | C10: Units | D10: NAV | E10: Amount | F10: Date | G10: Amount in/out
A11: Tata Liquid Fund Direct Growth | B11: REDEEM | C11: 2.55 | D11: 3891.11 | E11: 9926 | F11: 45488 | G11: 9926
A12: Tata Liquid Fund Direct Growth | B12: SWITCH PURCHASE | C12: 2.55 | D12: 3757.76 | E12: 9584 | F12: 45314 | G12: -9584
A13: TOTAL
F14: XIRR | G14: =XIRR(G11:G12,F11:F12) -> #NUM!
A15: ADITYA BIRLA SUN LIFE LIQUID FUND DIRECT PLAN - GROWTH
A17: Scheme Name | B17: Transaction Type | C17: Units | D17: NAV | E17: Amount | F17: Date | G17: Amount in/out
A18: ADITYA BIRLA SUN LIFE LIQUID FUND DIRECT PLAN - GROWTH | B18: SWITCH REDEEM | C18: 3.01 | D18: 334.82 | E18: 1009 | F18: 44393 | G18: 1009
A19: ADITYA BIRLA SUN LIFE LIQUID FUND DIRECT PLAN - GROWTH | B19: PURCHASE | C19: 3.01 | D19: 330.18 | E19: 995 | F19: 44242 | G19: -995
A20: TOTAL | C20: 0
F21: XIRR | G21: 0.034350881
A22: Parag Parikh Flexi Cap Fund Direct Growth
A24: Scheme Name | B24: Transaction Type | C24: Units | D24: NAV | E24: Amount | F24: Date | G24: Amount in/out
A25: Parag Parikh Flexi Cap Fund Direct Growth | B25: SWITCH REDEEM | C25: 19.19 | D25: 71.31 | E25: 1368 | F25: 45310 | G25: 1368
A26: Parag Parikh Flexi Cap Fund Direct Growth | B26: SWITCH PURCHASE | C26: 19.19 | D26: 53.35 | E26: 1023 | F26: 44526 | G26: -1023
A27: TOTAL | C27: 0
F28: XIRR | G28: 0.14487665
A29: ADITYA BIRLA SUN LIFE CORPORATE BOND FUND - GROWTH-DIRECT PLAN
A31: Scheme Name | B31: Transaction Type | C31: Units | D31: NAV | E31: Amount | F31: Date | G31: Amount in/out
A32: ADITYA BIRLA SUN LIFE CORPORATE BOND FUND - GROWTH-DIRECT PLAN | B32: SWITCH REDEEM | C32: 11.4 | D32: 89.9 | E32: 1024 | F32: 44524 | G32: 1024
A33: ADITYA BIRLA SUN LIFE CORPORATE BOND FUND - GROWTH-DIRECT PLAN | B33: SWITCH PURCHASE | C33: 11.4 | D33: 88.51 | E33: 1009 | F33: 44393 | G33: -1009
A34: ADITYA BIRLA SUN LIFE CORPORATE BOND FUND - GROWTH-DIRECT PLAN | B34: REDEEM | C34: 11.56 | D34: 86.06 | E34: 995 | F34: 44242 | G34: 995
A35: ADITYA BIRLA SUN LIFE CORPORATE BOND FUND - GROWTH-DIRECT PLAN | B35: PURCHASE | C35: 11.56 | D35: 86.48 | E35: 999 | F35: 44208 | G35: -999
A36: TOTAL | C36: 0
F37: XIRR | G37: 0.024111205
A38: ICICI Prudential Liquid Fund Direct Plan Growth
A40: Scheme Name | B40: Transaction Type | C40: Units | D40: NAV | E40: Amount | F40: Date | G40: Amount in/out
A41: ICICI Prudential Liquid Fund Direct Plan Growth | B41: REDEEM | C41: 52.61 | D41: 365.05 | E41: 19203 | F41: 45488 | G41: 19203
A42: ICICI Prudential Liquid Fund Direct Plan Growth | B42: SWITCH PURCHASE | C42: 52.61 | D42: 352.45 | E42: 18541 | F42: 45314 | G42: -18541
A43: TOTAL
F44: XIRR | G44: =XIRR(G41:G42,F41:F42) -> #NUM!
A45: Parag Parikh Arbitrage Fund Direct Growth
A47: Scheme Name | B47: Transaction Type | C47: Units | D47: NAV | E47: Amount | F47: Date | G47: Amount in/out
...

Sheet Stocks Transaction
A1: Personal Details
A2: Name
A3: Unique Client Code
A5: =CONCATENATE("P&L Statement for stocks from 11-06-2020 TO ", TEXT(TODAY(), "DD-MM-YYYY")) -> P&L Statement for stocks from 11-06-2020 TO 24-07-2025
A8: Stocks
A10: Stock name | B10: ISIN | C10: Quantity | D10: Buy date | E10: Buy price | F10: Buy value | G10: Sell date | H10: Sell price | I10: Sell value | J10: UN/Realised P&L
A11: FEDERAL BANK LTD | B11: INE171A01029 | C11: 2 | D11: 44130 | E11: 56.3 | F11: 112.6 | G11: 44186 | H11: 65.2 | I11: 130.4 | J11: 17.8
A12: VODAFONE IDEA LIMITED | B12: INE669E01016 | C12: 6 | D12: 44130 | E12: 9.05 | F12: 54.3 | G12: 44186 | H12: 9.9 | I12: 59.4 | J12: 5.1
A13: ITC LTD | B13: INE154A01025 | C13: 2 | D13: 44130 | E13: 171.5 | F13: 343 | G13: 44186 | H13: 212.6 | I13: 425.2 | J13: 82.2
A14: TATA MOTORS LIMITED | B14: INE155A01022 | C14: 1 | D14: 44130 | E14: 138.4 | F14: 138.4 | G14: 44186 | H14: 176.75 | I14: 176.75 | J14: 38.35
A15: SPICEJET LTD. | B15: INE285B01017 | C15: 2 | D15: 44130 | E15: 52.65 | F15: 105.3 | G15: 44186 | H15: 97.05 | I15: 194.1 | J15: 88.8
A16: YES BANK LIMITED | B16: INE528G01035 | C16: 6 | D16: 44130 | E16: 13.95 | F16: 83.7 | G16: 44186 | H16: 18.7 | I16: 112.2 | J16: 28.5
A17: VISA STEEL LIMITED | B17: INE286H01012 | C17: 1 | D17: 44132 | E17: 6.15 | F17: 6.15 | G17: 44147 | H17: 5.5 | I17: 5.5 | J17: -0.65
A18: GTL INFRA.LTD | B18: INE221H01019 | C18: 1 | D18: 44134 | E18: 0.65 | F18: 0.65 | G18: 44147 | H18: 0.6 | I18: 0.6 | J18: -0.05
A19: PAZEL | B19: INE040N01029 | C19: 1 | D19: 44140 | E19: 0.25 | F19: 0.25 | G19: 44149 | H19: 0.2 | I19: 0.2 | J19: -0.05
A20: ZEE ENTERTAINMENT ENT LTD | B20: INE256A01028 | C20: 3 | D20: 44037 | E20: 141.12 | F20: 423.36 | G20: 45593 | H20: 119.7 | I20: 359.1 | J20: -64.26
A21: ZEE ENTERTAINMENT ENT LTD | B21: INE256A01028 | C21: 1 | D21: 45523 | E21: 135.4 | F21: 135.4 | G21: 45593 | H21: 119.7 | I21: 119.7 | J21: -15.7
A22: TOTAL | F22: =SUM(F11:F21) -> 1403.11 | I22: =SUM(I11:I21) -> 1583.15 | J22: =SUM(J11:J21) -> 180.04
I23: Abs Returns | J23: =J22/F22 -> 0.12831496
A25: ETF
A27: Stock name | B27: ISIN | C27: Quantity | D27: Buy date | E27: Buy price | F27: Buy value | G27: Sell date | H27: Sell price | I27: Sell value | J27: UN/Realised P&L
A28: MOTILAL OS NASDAQ100 ETF | B28: INF247L01AP3 | C28: 8 | D28: 44741 | E28: 90.2 | F28: 721.6 | G28: 45357 | H28: 145.25 | I28: 1162 | J28: 440.4
A29: MOTILAL OS NASDAQ100 ETF | B29: INF247L01AP3 | C29: 5 | D29: 44750 | E29: 93.98 | F29: 469.9 | G29: 45357 | H29: 145.25 | I29: 726.25 | J29: 256.35
A30: MOTILAL OS NASDAQ100 ETF | B30: INF247L01AP3 | C30: 6 | D30: 44760 | E30: 94.38 | F30: 566.28 | G30: 45357 | H30: 145.25 | I30: 871.5 | J30: 305.22
A31: MOTILAL OS NASDAQ100 ETF | B31: INF247L01AP3 | C31: 5 | D31: 44792 | E31: 104.62 | F31: 523.1 | G31: 45357 | H31: 145.25 | I31: 726.25 | J31: 203.15
A32: MOTILAL OS NASDAQ100 ETF | B32: INF247L01AP3 | C32: 5 | D32: 44816 | E32: 98.33 | F32: 491.65 | G32: 45357 | H32: 145.25 | I32: 726.25 | J32: 234.6
A33: MOTILAL OS NASDAQ100 ETF | B33: INF247L01AP3 | C33: 5 | D33: 44844 | E33: 91.47 | F33: 457.35 | G33: 45357 | H33: 145.25 | I33: 726.25 | J33: 268.9
A34: MOTILAL OS NASDAQ100 ETF | B34: INF247L01AP3 | C34: 5 | D34: 44882 | E34: 93.01 | F34: 465.05 | G34: 45357 | H34: 145.25 | I34: 726.25 | J34: 261.2
A35: MOTILAL OS NASDAQ100 ETF | B35: INF247L01AP3 | C35: 6 | D35: 44914 | E35: 92.82 | F35: 556.92 | G35: 45357 | H35: 145.25 | I35: 871.5 | J35: 314.58
A36: MOTILAL OS NASDAQ100 ETF | B36: INF247L01AP3 | C36: 10 | D36: 44960 | E36: 99.96 | F36: 999.6 | G36: 45357 | H36: 145.25 | I36: 1452.5 | J36: 452.9 | K36: =IFERROR(__xludf.DUMMYFUNCTION("(-SUM(F28:F44)+SUM(I28:I44))"),7381.33999999999) -> 7381.34 | L36: Returns till now
A37: MOTILAL OS NASDAQ100 ETF | B37: INF247L01AP3 | C37: 9 | D37: 44965 | E37: 102.01 | F37: 918.09 | G37: 45357 | H37: 145.25 | I37: 1307.25 | J37: 389.16 | K37: =IFERROR(__xludf.DUMMYFUNCTION("(-SUM(F28:F37)+SUM(I28:I37))/SUM(F28:F37)"),0.50675739196115) -> 0.50675739 | L37: in percentage
A38: MOTILAL OS NASDAQ100 ETF | B38: INF247L01AP4 | C38: 60 | D38: 45498 | E38: 159.17 | F38: 9550.2 | G38: =TODAY() -> 45862 | H38: =IFERROR(__xludf.DUMMYFUNCTION("GOOGLEFINANCE(""MON100"")"),200.41) -> 200.41 | I38: =C38*H38 -> 12024.6 | J38: =I38-F38 -> 2474.4
A39: MOTILAL OS NASDAQ100 ETF | B39: INF247L01AP3 | C39: 33 | D39: 45523 | E39: 159.69 | F39: 5269.77 | G39: =TODAY() -> 45862 | H39: =IFERROR(__xludf.DUMMYFUNCTION("GOOGLEFINANCE(""MON100"")"),200.41) -> 200.41 | I39: =C39*H39 -> 6613.53 | J39: =I39-F39 -> 1343.76
A40: MOTILAL OS NASDAQ100 ETF | B40: INF247L01AP3 | C40: 7 | D40: 45741 | E40: 186.06 | F40: 1302.42 | G40: =TODAY() -> 45862 | H40: =IFERROR(__xludf.DUMMYFUNCTION("GOOGLEFINANCE(""MON100"")"),200.41) -> 200.41 | I40: =C40*H40 -> 1402.87 | J40: =I40-F40 -> 100.45
A41: MOTILAL OS NASDAQ100 ETF | B41: INF247L01AP3 | C41: 3 | D41: 45764 | E41: 164.48 | F41: 493.44 | G41: =TODAY() -> 45862 | H41: =IFERROR(__xludf.DUMMYFUNCTION("GOOGLEFINANCE(""MON100"")"),200.41) -> 200.41 | I41: =C41*H41 -> 601.23 | J41: =I41-F41 -> 107.79
A42: MOTILAL OS NASDAQ100 ETF | B42: INF247L01AP3 | C42: 8 | D42: 45817 | E42: 181.78 | F42: 1454.24 | G42: =TODAY() -> 45862 | H42: =IFERROR(__xludf.DUMMYFUNCTION("GOOGLEFINANCE(""MON100"")"),200.41) -> 200.41 | I42: =C42*H42 -> 1603.28 | J42: =I42-F42 -> 149.04
A43: MOTILAL OS NASDAQ100 ETF | B43: INF247L01AP3 | C43: 3 | D43: 45825 | E43: 181.79 | F43: 545.37 | G43: =TODAY() -> 45862 | H43: =IFERROR(__xludf.DUMMYFUNCTION("GOOGLEFINANCE(""MON100"")"),200.41) -> 200.41 | I43: =C43*H43 -> 601.23 | J43: =I43-F43 -> 55.86
A44: MOTILAL OS NASDAQ100 ETF | B44: INF247L01AP3 | C44: 3 | D44: 45854 | E44: 192.55 | F44: 577.65 | G44: =TODAY() -> 45862 | H44: =IFERROR(__xludf.DUMMYFUNCTION("GOOGLEFINANCE(""MON100"")"),200.41) -> 200.41 | I44: =C44*H44 -> 601.23 | J44: =I44-F44 -> 23.58
A45: TOTAL (current) | F45: =SUM(F38:F44) -> 19193.09 | I45: =SUM(I38:I44) -> 23447.97 | J45: =I45-F45 -> 4254.88
I46: Abs Returns | J46: =J45/F45 -> 0.22168812
...
