Workbook

Sheet Portfolio  Holdings
H1: Difference
B2: MF + ETF PORTFOLIO XIRR | D2: =C315 -> 0.14893689 | F2: NIFTY Return in the same period: | G2: =(F7/F6)^(1/F8) - 1 -> #N/A | H2: =D2-G2 -> #N/A
B3: DATES | C3: AMOUNT | D3: Cum Sum
B4: 44126 | C4: -100 | D4: =-(SUM($C$4:C4)) -> 100 | E4: =B4 -> 44126 | F4: =E4 -> 44126 | G4: CRYPTO
B5: 44126 | C5: -499 | D5: =-(SUM($C$4:C5)) -> 599 | E5: =B5 -> 44126 | F5: =TODAY()-1 -> 46047
B6: 44126 | C6: -499 | D6: =-(SUM($C$4:C6)) -> 1098 | E6: =B6 -> 44126 | F6: =IFERROR(__xludf.DUMMYFUNCTION("INDEX(GOOGLEFINANCE(""NIFTY_50"", ""price"", F4), 2, 2)"),11896.45) -> 11896.45 | G6: INVESTED | H6: ='Crypto Analysis'!G22 -> 9946.752 | J6: BTC | K6: =IFERROR(__xludf.DUMMYFUNCTION("GOOGLEFINANCE(""BTCINR"")"),8105255.146) -> 8105255.1
B7: 44152 | C7: 101 | D7: =-(SUM($C$4:C7)) -> 997 | E7: =B7 -> 44152 | F7: =IFERROR(__xludf.DUMMYFUNCTION("INDEX(GOOGLEFINANCE(""INDEXNSE:NIFTY_50"", ""close"", F5), 2, 2)"),"#N/A") -> #N/A | G7: Portfolio Value | H7: ='Crypto Analysis'!G23 -> 12489.306 | J7: ETH | K7: =IFERROR(__xludf.DUMMYFUNCTION("GOOGLEFINANCE(""ETHINR"")"),268960.1667) -> 268960.17
B8: 44162 | C8: 495 | D8: =-(SUM($C$4:C8)) -> 502 | E8: =B8 -> 44162 | F8: =(F5-F4)/365.25 -> 5.2594114 | G8: Returns | H8: ='Crypto Analysis'!G24 -> 2542.5539
B9: 44169 | C9: -499 | D9: =-(SUM($C$4:C9)) -> 1001 | E9: =B9 -> 44169 | H9: ='Crypto Analysis'!G25 -> 0.25561649
B10: 44180 | C10: -499 | D10: =-(SUM($C$4:C10)) -> 1500 | E10: =B10 -> 44180
B11: 44181 | C11: -499 | D11: =-(SUM($C$4:C11)) -> 1999 | E11: =B11 -> 44181
B12: 44208 | C12: -999 | D12: =-(SUM($C$4:C12)) -> 2998 | E12: =B12 -> 44208 | G12: Mutual Fund
B13: 44211 | C13: -499 | D13: =-(SUM($C$4:C13)) -> 3497 | E13: =B13 -> 44211
B14: 44242 | C14: -499 | D14: =-(SUM($C$4:C14)) -> 3996 | E14: =B14 -> 44242 | G14: Invested Value | H14: Profit | I14: Today
B15: 44242 | C15: -995 | D15: =-(SUM($C$4:C15)) -> 4991 | E15: =B15 -> 44242 | G15: ='MF holdings and transactions'!A309 -> 99758 | H15: ='MF holdings and transactions'!B309 -> 34903 | I15: ='MF holdings and transactions'!C309 -> 67668.996
B16: 44242 | C16: 995 | D16: =-(SUM($C$4:C16)) -> 3996 | E16: =B16 -> 44242
B17: 44242 | C17: -499 | D17: =-(SUM($C$4:C17)) -> 4495 | E17: =B17 -> 44242 | G17: ETF
B18: 44270 | C18: -499 | D18: =-(SUM($C$4:C18)) -> 4994 | E18: =B18 -> 44270
B19: 44270 | C19: -499 | D19: =-(SUM($C$4:C19)) -> 5493 | E19: =B19 -> 44270 | G19: Invested Value | H19: Profit | I19: Today
B20: 44301 | C20: -499 | D20: =-(SUM($C$4:C20)) -> 5992 | E20: =B20 -> 44301 | G20: ='Stocks Transaction'!I55 -> 27189.47 | H20: ='Stocks Transaction'!J55 -> 9296 | I20: ='Stocks Transaction'!I49 -> 29750
B21: 44301 | C21: -499 | D21: =-(SUM($C$4:C21)) -> 6491 | E21: =B21 -> 44301 | J21: Profit + Today
B22: 44333 | C22: -499 | D22: =-(SUM($C$4:C22)) -> 6990 | E22: =B22 -> 44333 | F22: TOTAL | G22: =G15+G20 -> 126947.47 | H22: =H15+H20 -> 44199 | I22: =I15+I20 -> 97418.996 | J22: =H22+I22 -> 141618
B23: 44333 | C23: -499 | D23: =-(SUM($C$4:C23)) -> 7489 | E23: =B23 -> 44333 | I23: ABS RETURN | J23: =(J22-G22)/G22 -> 0.11556375
B24: 44362 | C24: -499 | D24: =-(SUM($C$4:C24)) -> 7988 | E24: =B24 -> 44362
B25: 44362 | C25: -499 | D25: =-(SUM($C$4:C25)) -> 8487 | E25: =B25 -> 44362
B26: 44376 | C26: -3830 | D26: =-(SUM($C$4:C26)) -> 12317 | E26: =B26 -> 44376
B27: 44376 | C27: 3830 | D27: =-(SUM($C$4:C27)) -> 8487 | E27: =B27 -> 44376
B28: 44392 | C28: -499 | D28: =-(SUM($C$4:C28)) -> 8986 | E28: =B28 -> 44392
B29: 44393 | C29: 1009 | D29: =-(SUM($C$4:C29)) -> 7977 | E29: =B29 -> 44393
B30: 44393 | C30: -1009 | D30: =-(SUM($C$4:C30)) -> 8986 | E30: =B30 -> 44393
B31: 44393 | C31: -499 | D31: =-(SUM($C$4:C31)) -> 9485 | E31: =B31 -> 44393
B32: 44393 | C32: -499 | D32: =-(SUM($C$4:C32)) -> 9984 | E32: =B32 -> 44393
B33: 44393 | C33: -499 | D33: =-(SUM($C$4:C33)) -> 10483 | E33: =B33 -> 44393
B34: 44420 | C34: -199 | D34: =-(SUM($C$4:C34)) -> 10682 | E34: =B34 -> 44420
B35: 44424 | C35: -499 | D35: =-(SUM($C$4:C35)) -> 11181 | E35: =B35 -> 44424
... B47: 44515 | C47: -199 | D47: =-(SUM($C$4:C47)) -> 16269 | E47: =B47 -> 44515
B48: 44515 | C48: -499 | D48: =-(SUM($C$4:C48)) -> 16768 | E48: =B48 -> 44515 | G48: Guideline to update sheet
B49: 44515 | C49: -499 | D49: =-(SUM($C$4:C49)) -> 17267 | E49: =B49 -> 44515 | G49: 1) download mutual fund transation report (1) and mutual fund portfolio summary (2)
B50: 44524 | C50: -7955 | D50: =-(SUM($C$4:C50)) -> 25222 | E50: =B50 -> 44524 | G50: 2) copy the new entries from 1 and paste in transactions. add comments if the purchase is special or write the reason if redeemed or switched
B51: 44524 | C51: 1024 | D51: =-(SUM($C$4:C51)) -> 24198 | E51: =B51 -> 44524 | G51: 3) fill units, invested value from 2 to portfolio
...

Sheet MF holdings and transactions
A3: Personal Details
A4: Name | B4: Param Prakash
A5: Mobile Number | B5: 9968481838
A6: PAN | B6: BCEPP5864L
B9: DATE
A10: TRANSACTIONS TILL | B10: =TODAY() -> 46048
P11: XIRR (WITHOUT SWITCH)
A12: Scheme Name | B12: Transaction Type | C12: Units | D12: NAV | E12: Amount | F12: Date | G12: Amount in/out | H12: ="2000 SIP Going (" & IF(DAY(TODAY()) > 17, DATEDIF(DATE(2024, 1, 1), TODAY(), "M") + 1, DATEDIF(DATE(2024, 1, 1), TODAY(), "M")) & ")" -> 2000 SIP Going (25) | P12: DATES | Q12: AMOUNT
A14: Nippon India Nifty Midcap 150 Index Fund Direct Growth | B14: PURCHASE | C14: 19.55 | D14: 25.58 | E14: 499 | F14: 46006 | G14: =IF(E14="", "", IF(OR(B14="PURCHASE", B14="SWITCH PURCHASE"), E14*-1, E14)) -> -499 | P14: 46006 | Q14: -499
A15: UTI Nifty200 Momentum 30 Index Fund Direct Growth | B15: PURCHASE | C15: 22.99 | D15: 21.75 | E15: 499 | F15: 46006 | G15: =IF(E15="", "", IF(OR(B15="PURCHASE", B15="SWITCH PURCHASE"), E15*-1, E15)) -> -499 | P15: 46006 | Q15: -499
A16: HDFC Short Term Debt Fund Direct Plan Growth | B16: PURCHASE | C16: 14.69 | D16: 34.03 | E16: 499 | F16: 46006 | G16: =IF(E16="", "", IF(OR(B16="PURCHASE", B16="SWITCH PURCHASE"), E16*-1, E16)) -> -499 | P16: 46006 | Q16: -499
A17: Nippon India Nifty Midcap 150 Index Fund Direct Growth | B17: PURCHASE | C17: 19.25 | D17: 25.97 | E17: 499 | F17: 45978 | G17: =IF(E17="", "", IF(OR(B17="PURCHASE", B17="SWITCH PURCHASE"), E17*-1, E17)) -> -499 | P17: 45978 | Q17: -499
A18: UTI Nifty200 Momentum 30 Index Fund Direct Growth | B18: PURCHASE | C18: 22.51 | D18: 22.21 | E18: 499 | F18: 45978 | G18: =IF(E18="", "", IF(OR(B18="PURCHASE", B18="SWITCH PURCHASE"), E18*-1, E18)) -> -499 | P18: 45978 | Q18: -499
A19: HDFC Short Term Debt Fund Direct Plan Growth | B19: PURCHASE | C19: 14.71 | D19: 33.98 | E19: 499 | F19: 45978 | G19: =IF(E19="", "", IF(OR(B19="PURCHASE", B19="SWITCH PURCHASE"), E19*-1, E19)) -> -499 | P19: 45978 | Q19: -499
A20: Nippon India Nifty Midcap 150 Index Fund Direct Growth | B20: PURCHASE | C20: 19.87 | D20: 25.16 | E20: 499 | F20: 45945 | G20: =IF(E20="", "", IF(OR(B20="PURCHASE", B20="SWITCH PURCHASE"), E20*-1, E20)) -> -499 | P20: 45945 | Q20: -499
A21: UTI Nifty200 Momentum 30 Index Fund Direct Growth | B21: PURCHASE | C21: 22.84 | D21: 21.89 | E21: 499 | F21: 45945 | G21: =IF(E21="", "", IF(OR(B21="PURCHASE", B21="SWITCH PURCHASE"), E21*-1, E21)) -> -499 | P21: 45945 | Q21: -499
A22: HDFC Short Term Debt Fund Direct Plan Growth | B22: PURCHASE | C22: 14.8 | D22: 33.77 | E22: 499 | F22: 45945 | G22: =IF(E22="", "", IF(OR(B22="PURCHASE", B22="SWITCH PURCHASE"), E22*-1, E22)) -> -499 | P22: 45945 | Q22: -499
A23: Nippon India Nifty Midcap 150 Index Fund Direct Growth | B23: PURCHASE | C23: 19.77 | D23: 25.3 | E23: 499 | F23: 45918 | G23: =IF(E23="", "", IF(OR(B23="PURCHASE", B23="SWITCH PURCHASE"), E23*-1, E23)) -> -499 | P23: 45918 | Q23: -499
A24: Nippon India Nifty Midcap 150 Index Fund Direct Growth | B24: PURCHASE | C24: 19.98 | D24: 25.02 | E24: 499 | F24: 45915 | G24: =IF(E24="", "", IF(OR(B24="PURCHASE", B24="SWITCH PURCHASE"), E24*-1, E24)) -> -499 | P24: 45915 | Q24: -499
A25: UTI Nifty200 Momentum 30 Index Fund Direct Growth | B25: PURCHASE | C25: 23.41 | D25: 21.36 | E25: 499 | F25: 45915 | G25: =IF(E25="", "", IF(OR(B25="PURCHASE", B25="SWITCH PURCHASE"), E25*-1, E25)) -> -499 | P25: 45915 | Q25: -499
... A43: Nippon India Nifty Midcap 150 Index Fund Direct Growth | B43: PURCHASE | C43: 55.61 | D43: 22.11 | E43: 1230 | F43: 45743 | G43: =IF(E43="", "", IF(OR(B43="PURCHASE", B43="SWITCH PURCHASE"), E43*-1, E43)) -> -1230 | P43: 45743 | Q43: -1230
A44: HDFC Short Term Debt Fund Direct Plan Growth | B44: REDEEM | C44: 78.98 | D44: 32.1 | E44: 2536 | F44: 45737 | G44: 2536 | P44: 45737 | Q44: 2536
A45: HDFC Short Term Debt Fund Direct Plan Growth | B45: PURCHASE | C45: 15.62 | D45: 32.01 | E45: 499 | F45: 45733 | G45: =IF(E45="", "", IF(OR(B45="PURCHASE", B45="SWITCH PURCHASE"), E45*-1, E45)) -> -499 | P45: 45733 | Q45: -499
A46: UTI Nifty200 Momentum 30 Index Fund Direct Growth | B46: PURCHASE | C46: 26.92 | D46: 18.57 | E46: 499 | F46: 45733 | G46: =IF(E46="", "", IF(OR(B46="PURCHASE", B46="SWITCH PURCHASE"), E46*-1, E46)) -> -499 | P46: 45733 | Q46: -499
A47: Nippon India Nifty Midcap 150 Index Fund Direct Growth | B47: PURCHASE | C47: 24.02 | D47: 20.81 | E47: 499 | F47: 45733 | G47: =IF(E47="", "", IF(OR(B47="PURCHASE", B47="SWITCH PURCHASE"), E47*-1, E47)) -> -499 | P47: 45733 | Q47: -499
A48: Nippon India Nifty Midcap 150 Index Fund Direct Growth | B48: PURCHASE | C48: 24.02 | D48: 20.81 | E48: 499 | F48: 45733 | G48: =IF(E48="", "", IF(OR(B48="PURCHASE", B48="SWITCH PURCHASE"), E48*-1, E48)) -> -499 | P48: 45733 | Q48: -499
A49: UTI Nifty200 Momentum 30 Index Fund Direct Growth | B49: PURCHASE | C49: 25.61 | D49: 19.52 | E49: 499 | F49: 45705 | G49: =IF(E49="", "", IF(OR(B49="PURCHASE", B49="SWITCH PURCHASE"), E49*-1, E49)) -> -499 | P49: 45705 | Q49: -499
A50: Nippon India Nifty Midcap 150 Index Fund Direct Growth | B50: PURCHASE | C50: 23.53 | D50: 21.25 | E50: 499 | F50: 45705 | G50: =IF(E50="", "", IF(OR(B50="PURCHASE", B50="SWITCH PURCHASE"), E50*-1, E50)) -> -499 | P50: 45705 | Q50: -499
A51: HDFC Short Term Debt Fund Direct Plan Growth | B51: PURCHASE | C51: 15.69 | D51: 31.87 | E51: 499 | F51: 45705 | G51: =IF(E51="", "", IF(OR(B51="PURCHASE", B51="SWITCH PURCHASE"), E51*-1, E51)) -> -499 | P51: 45705 | Q51: -499
A52: Nippon India Nifty Midcap 150 Index Fund Direct Growth | B52: PURCHASE | C52: 23.53 | D52: 21.25 | E52: 499 | F52: 45705 | G52: =IF(E52="", "", IF(OR(B52="PURCHASE", B52="SWITCH PURCHASE"), E52*-1, E52)) -> -499 | P52: 45705 | Q52: -499
A53: Nippon India Nifty Midcap 150 Index Fund Direct Growth | B53: PURCHASE | C53: 21.48 | D53: 23.28 | E53: 499 | F53: 45674 | G53: =IF(E53="", "", IF(OR(B53="PURCHASE", B53="SWITCH PURCHASE"), E53*-1, E53)) -> -499 | P53: 45674 | Q53: -499
A54: UTI Nifty200 Momentum 30 Index Fund Direct Growth | B54: PURCHASE | C54: 23.59 | D54: 21.19 | E54: 499 | F54: 45672 | G54: =IF(E54="", "", IF(OR(B54="PURCHASE", B54="SWITCH PURCHASE"), E54*-1, E54)) -> -499 | P54: 45672 | Q54: -499
A55: Nippon India Nifty Midcap 150 Index Fund Direct Growth | B55: PURCHASE | C55: 21.73 | D55: 23 | E55: 499 | F55: 45672 | G55: =IF(E55="", "", IF(OR(B55="PURCHASE", B55="SWITCH PURCHASE"), E55*-1, E55)) -> -499 | P55: 45672 | Q55: -499
A56: HDFC Short Term Debt Fund Direct Plan Growth | B56: PURCHASE | C56: 15.82 | D56: 31.6 | E56: 499 | F56: 45672 | G56: =IF(E56="", "", IF(OR(B56="PURCHASE", B56="SWITCH PURCHASE"), E56*-1, E56)) -> -499 | P56: 45672 | Q56: -499
... A64: HDFC Short Term Debt Fund Direct Plan Growth | B64: PURCHASE | C64: 15.98 | D64: 31.29 | E64: 499 | F64: 45614 | G64: =IF(E64="", "", IF(OR(B64="PURCHASE", B64="SWITCH PURCHASE"), E64*-1, E64)) -> -499 | P64: 45614 | Q64: -499
A65: Nippon India Nifty Midcap 150 Index Fund Direct Growth | B65: PURCHASE | C65: 83.11 | D65: 24.06 | E65: 1999 | F65: 45596 | G65: =IF(E65="", "", IF(OR(B65="PURCHASE", B65="SWITCH PURCHASE"), E65*-1, E65)) -> -1999 | H65: Total 4593 taken out here | P65: 45596 | Q65: -1999
A66: UTI Nifty200 Momentum 30 Index Fund Direct Growth | B66: PURCHASE | C66: 117.68 | D66: 23.79 | E66: 2799 | F66: 45596 | G66: =IF(E66="", "", IF(OR(B66="PURCHASE", B66="SWITCH PURCHASE"), E66*-1, E66)) -> -2799 | P66: 45596 | Q66: -2799
A67: HDFC Short Term Debt Fund Direct Plan Growth | B67: REDEEM | C67: 299.91 | D67: 31.16 | E67: 9346 | F67: 45593 | G67: =IF(E67="", "", IF(OR(B67="PURCHASE", B67="SWITCH PURCHASE"), E67*-1, E67)) -> 9346 | P67: 45593 | Q67: 9346
A68: UTI Nifty200 Momentum 30 Index Fund Direct Growth | B68: PURCHASE | C68: 19.42 | D68: 25.74 | E68: 499 | F68: 45581 | G68: =IF(E68="", "", IF(OR(B68="PURCHASE", B68="SWITCH PURCHASE"), E68*-1, E68)) -> -499 | P68: 45581 | Q68: -499
A69: MOTILAL OSWAL NASDAQ 100 FUND OF FUND - DIRECT GROWTH | B69: PURCHASE | C69: 14.2 | D69: 35.21 | E69: 499 | F69: 45581 | G69: =IF(E69="", "", IF(OR(B69="PURCHASE", B69="SWITCH PURCHASE"), E69*-1, E69)) -> -499 | P69: 45581 | Q69: -499
...

Sheet MF CAS
A1: ICICI Prudential Technology Fund - Direct - Growth
A3: Scheme Name | B3: Transaction Type | C3: Units | D3: NAV | E3: Amount | F3: Date | G3: Amount in/out
A4: ICICI Prudential Technology Fund - Direct - Growth | B4: REDEEM | C4: 1.1 | D4: 91.63 | E4: 101 | F4: 44152 | G4: 101
A5: ICICI Prudential Technology Fund - Direct - Growth | B5: PURCHASE | C5: 1.1 | D5: 90.46 | E5: 100 | F5: 44126 | G5: -100
A6: TOTAL | C6: 0
F7: XIRR | G7: 0.14991421
A8: Tata Liquid Fund Direct Growth
A10: Scheme Name | B10: Transaction Type | C10: Units | D10: NAV | E10: Amount | F10: Date | G10: Amount in/out
A11: Tata Liquid Fund Direct Growth | B11: REDEEM | C11: 2.55 | D11: 3891.11 | E11: 9926 | F11: 45488 | G11: 9926
A12: Tata Liquid Fund Direct Growth | B12: SWITCH PURCHASE | C12: 2.55 | D12: 3757.76 | E12: 9584 | F12: 45314 | G12: -9584
A13: TOTAL
F14: XIRR | G14: =XIRR(G11:G12,F11:F12) -> 0.076323128
A15: ADITYA BIRLA SUN LIFE LIQUID FUND DIRECT PLAN - GROWTH
A17: Scheme Name | B17: Transaction Type | C17: Units | D17: NAV | E17: Amount | F17: Date | G17: Amount in/out
A18: ADITYA BIRLA SUN LIFE LIQUID FUND DIRECT PLAN - GROWTH | B18: SWITCH REDEEM | C18: 3.01 | D18: 334.82 | E18: 1009 | F18: 44393 | G18: 1009
A19: ADITYA BIRLA SUN LIFE LIQUID FUND DIRECT PLAN - GROWTH | B19: PURCHASE | C19: 3.01 | D19: 330.18 | E19: 995 | F19: 44242 | G19: -995
A20: TOTAL | C20: 0
F21: XIRR | G21: 0.034350881
A22: Parag Parikh Flexi Cap Fund Direct Growth
A24: Scheme Name | B24: Transaction Type | C24: Units | D24: NAV | E24: Amount | F24: Date | G24: Amount in/out
A25: Parag Parikh Flexi Cap Fund Direct Growth | B25: SWITCH REDEEM | C25: 19.19 | D25: 71.31 | E25: 1368 | F25: 45310 | G25: 1368
A26: Parag Parikh Flexi Cap Fund Direct Growth | B26: SWITCH PURCHASE | C26: 19.19 | D26: 53.35 | E26: 1023 | F26: 44526 | G26: -1023
A27: TOTAL | C27: 0
F28: XIRR | G28: 0.14487665
A29: ADITYA BIRLA SUN LIFE CORPORATE BOND FUND - GROWTH-DIRECT PLAN
A31: Scheme Name | B31: Transaction Type | C31: Units | D31: NAV | E31: Amount | F31: Date | G31: Amount in/out
A32: ADITYA BIRLA SUN LIFE CORPORATE BOND FUND - GROWTH-DIRECT PLAN | B32: SWITCH REDEEM | C32: 11.4 | D32: 89.9 | E32: 1024 | F32: 44524 | G32: 1024
A33: ADITYA BIRLA SUN LIFE CORPORATE BOND FUND - GROWTH-DIRECT PLAN | B33: SWITCH PURCHASE | C33: 11.4 | D33: 88.51 | E33: 1009 | F33: 44393 | G33: -1009
A34: ADITYA BIRLA SUN LIFE CORPORATE BOND FUND - GROWTH-DIRECT PLAN | B34: REDEEM | C34: 11.56 | D34: 86.06 | E34: 995 | F34: 44242 | G34: 995
A35: ADITYA BIRLA SUN LIFE CORPORATE BOND FUND - GROWTH-DIRECT PLAN | B35: PURCHASE | C35: 11.56 | D35: 86.48 | E35: 999 | F35: 44208 | G35: -999
A36: TOTAL | C36: 0
F37: XIRR | G37: 0.024111205
A38: ICICI Prudential Liquid Fund Direct Plan Growth
A40: Scheme Name | B40: Transaction Type | C40: Units | D40: NAV | E40: Amount | F40: Date | G40: Amount in/out
A41: ICICI Prudential Liquid Fund Direct Plan Growth | B41: REDEEM | C41: 52.61 | D41: 365.05 | E41: 19203 | F41: 45488 | G41: 19203
A42: ICICI Prudential Liquid Fund Direct Plan Growth | B42: SWITCH PURCHASE | C42: 52.61 | D42: 352.45 | E42: 18541 | F42: 45314 | G42: -18541
A43: TOTAL
F44: XIRR | G44: =XIRR(G41:G42,F41:F42) -> 0.076367122
A45: Parag Parikh Arbitrage Fund Direct Growth
A47: Scheme Name | B47: Transaction Type | C47: Units | D47: NAV | E47: Amount | F47: Date | G47: Amount in/out
...

Sheet Stocks Transaction
A1: Personal Details
A2: Name | B2: Param Prakash
A3: Unique Client Code | B3: 2982190678
A5: =CONCATENATE("P&L Statement for stocks from 11-06-2020 TO ", TEXT(TODAY(), "DD-MM-YYYY")) -> P&L Statement for stocks from 11-06-2020 TO 26-01-2026
A8: Stocks
A10: Stock name | B10: ISIN | C10: Quantity | D10: Buy date | E10: Buy price | F10: Buy value | G10: Sell date | H10: Sell price | I10: Sell value | J10: UN/Realised P&L
A11: FEDERAL BANK LTD | B11: INE171A01029 | C11: 2 | D11: 44130 | E11: 56.3 | F11: 112.6 | G11: 44186 | H11: 65.2 | I11: 130.4 | J11: 17.8
A12: VODAFONE IDEA LIMITED | B12: INE669E01016 | C12: 6 | D12: 44130 | E12: 9.05 | F12: 54.3 | G12: 44186 | H12: 9.9 | I12: 59.4 | J12: 5.1
A13: ITC LTD | B13: INE154A01025 | C13: 2 | D13: 44130 | E13: 171.5 | F13: 343 | G13: 44186 | H13: 212.6 | I13: 425.2 | J13: 82.2
A14: TATA MOTORS LIMITED | B14: INE155A01022 | C14: 1 | D14: 44130 | E14: 138.4 | F14: 138.4 | G14: 44186 | H14: 176.75 | I14: 176.75 | J14: 38.35
A15: SPICEJET LTD. | B15: INE285B01017 | C15: 2 | D15: 44130 | E15: 52.65 | F15: 105.3 | G15: 44186 | H15: 97.05 | I15: 194.1 | J15: 88.8
A16: YES BANK LIMITED | B16: INE528G01035 | C16: 6 | D16: 44130 | E16: 13.95 | F16: 83.7 | G16: 44186 | H16: 18.7 | I16: 112.2 | J16: 28.5
A17: VISA STEEL LIMITED | B17: INE286H01012 | C17: 1 | D17: 44132 | E17: 6.15 | F17: 6.15 | G17: 44147 | H17: 5.5 | I17: 5.5 | J17: -0.65
A18: GTL INFRA.LTD | B18: INE221H01019 | C18: 1 | D18: 44134 | E18: 0.65 | F18: 0.65 | G18: 44147 | H18: 0.6 | I18: 0.6 | J18: -0.05
A19: PAZEL | B19: INE040N01029 | C19: 1 | D19: 44140 | E19: 0.25 | F19: 0.25 | G19: 44149 | H19: 0.2 | I19: 0.2 | J19: -0.05
A20: ZEE ENTERTAINMENT ENT LTD | B20: INE256A01028 | C20: 3 | D20: 44037 | E20: 141.12 | F20: 423.36 | G20: 45593 | H20: 119.7 | I20: 359.1 | J20: -64.26
A21: ZEE ENTERTAINMENT ENT LTD | B21: INE256A01028 | C21: 1 | D21: 45523 | E21: 135.4 | F21: 135.4 | G21: 45593 | H21: 119.7 | I21: 119.7 | J21: -15.7
A22: TOTAL | F22: =SUM(F11:F21) -> 1403.11 | I22: =SUM(I11:I21) -> 1583.15 | J22: =SUM(J11:J21) -> 180.04
I23: Abs Returns | J23: =J22/F22 -> 0.12831496
A25: ETF
A27: Stock name | B27: ISIN | C27: Quantity | D27: Buy date | E27: Buy price | F27: Buy value | G27: Sell date | H27: Sell price | I27: Sell value | J27: UN/Realised P&L
A28: MOTILAL OS NASDAQ100 ETF | B28: INF247L01AP3 | C28: 8 | D28: 44741 | E28: 90.2 | F28: 721.6 | G28: 45357 | H28: 145.25 | I28: 1162 | J28: 440.4
A29: MOTILAL OS NASDAQ100 ETF | B29: INF247L01AP3 | C29: 5 | D29: 44750 | E29: 93.98 | F29: 469.9 | G29: 45357 | H29: 145.25 | I29: 726.25 | J29: 256.35
A30: MOTILAL OS NASDAQ100 ETF | B30: INF247L01AP3 | C30: 6 | D30: 44760 | E30: 94.38 | F30: 566.28 | G30: 45357 | H30: 145.25 | I30: 871.5 | J30: 305.22
A31: MOTILAL OS NASDAQ100 ETF | B31: INF247L01AP3 | C31: 5 | D31: 44792 | E31: 104.62 | F31: 523.1 | G31: 45357 | H31: 145.25 | I31: 726.25 | J31: 203.15
A32: MOTILAL OS NASDAQ100 ETF | B32: INF247L01AP3 | C32: 5 | D32: 44816 | E32: 98.33 | F32: 491.65 | G32: 45357 | H32: 145.25 | I32: 726.25 | J32: 234.6
A33: MOTILAL OS NASDAQ100 ETF | B33: INF247L01AP3 | C33: 5 | D33: 44844 | E33: 91.47 | F33: 457.35 | G33: 45357 | H33: 145.25 | I33: 726.25 | J33: 268.9
A34: MOTILAL OS NASDAQ100 ETF | B34: INF247L01AP3 | C34: 5 | D34: 44882 | E34: 93.01 | F34: 465.05 | G34: 45357 | H34: 145.25 | I34: 726.25 | J34: 261.2
A35: MOTILAL OS NASDAQ100 ETF | B35: INF247L01AP3 | C35: 6 | D35: 44914 | E35: 92.82 | F35: 556.92 | G35: 45357 | H35: 145.25 | I35: 871.5 | J35: 314.58
A36: MOTILAL OS NASDAQ100 ETF | B36: INF247L01AP3 | C36: 10 | D36: 44960 | E36: 99.96 | F36: 999.6 | G36: 45357 | H36: 145.25 | I36: 1452.5 | J36: 452.9 | K36: =(-SUM(F28:F44)+SUM(I28:I44)) -> 11779.37 | L36: Returns till now
A37: MOTILAL OS NASDAQ100 ETF | B37: INF247L01AP3 | C37: 9 | D37: 44965 | E37: 102.01 | F37: 918.09 | G37: 45357 | H37: 145.25 | I37: 1307.25 | J37: 389.16 | K37: =(-SUM(F28:F37)+SUM(I28:I37))/SUM(F28:F37) -> 0.50675739 | L37: in percentage
A38: MOTILAL OS NASDAQ100 ETF | B38: INF247L01AP4 | C38: 60 | D38: 45498 | E38: 159.17 | F38: 9550.2 | G38: =TODAY() -> 46048 | H38: =IFERROR(__xludf.DUMMYFUNCTION("GOOGLEFINANCE(""MON100"")"),238.0) -> 238 | I38: =C38*H38 -> 14280 | J38: =I38-F38 -> 4729.8
A39: MOTILAL OS NASDAQ100 ETF | B39: INF247L01AP3 | C39: 33 | D39: 45523 | E39: 159.69 | F39: 5269.77 | G39: =TODAY() -> 46048 | H39: =IFERROR(__xludf.DUMMYFUNCTION("GOOGLEFINANCE(""MON100"")"),238.0) -> 238 | I39: =C39*H39 -> 7854 | J39: =I39-F39 -> 2584.23
A40: MOTILAL OS NASDAQ100 ETF | B40: INF247L01AP3 | C40: 7 | D40: 45741 | E40: 186.06 | F40: 1302.42 | G40: =TODAY() -> 46048 | H40: =IFERROR(__xludf.DUMMYFUNCTION("GOOGLEFINANCE(""MON100"")"),238.0) -> 238 | I40: =C40*H40 -> 1666 | J40: =I40-F40 -> 363.58
A41: MOTILAL OS NASDAQ100 ETF | B41: INF247L01AP3 | C41: 3 | D41: 45764 | E41: 164.48 | F41: 493.44 | G41: =TODAY() -> 46048 | H41: =IFERROR(__xludf.DUMMYFUNCTION("GOOGLEFINANCE(""MON100"")"),238.0) -> 238 | I41: =C41*H41 -> 714 | J41: =I41-F41 -> 220.56
A42: MOTILAL OS NASDAQ100 ETF | B42: INF247L01AP3 | C42: 8 | D42: 45817 | E42: 181.78 | F42: 1454.24 | G42: =TODAY() -> 46048 | H42: =IFERROR(__xludf.DUMMYFUNCTION("GOOGLEFINANCE(""MON100"")"),238.0) -> 238 | I42: =C42*H42 -> 1904 | J42: =I42-F42 -> 449.76
A43: MOTILAL OS NASDAQ100 ETF | B43: INF247L01AP3 | C43: 3 | D43: 45825 | E43: 181.79 | F43: 545.37 | G43: =TODAY() -> 46048 | H43: =IFERROR(__xludf.DUMMYFUNCTION("GOOGLEFINANCE(""MON100"")"),238.0) -> 238 | I43: =C43*H43 -> 714 | J43: =I43-F43 -> 168.63
A44: MOTILAL OS NASDAQ100 ETF | B44: INF247L01AP3 | C44: 3 | D44: 45854 | E44: 192.55 | F44: 577.65 | G44: =TODAY() -> 46048 | H44: =IFERROR(__xludf.DUMMYFUNCTION("GOOGLEFINANCE(""MON100"")"),238.0) -> 238 | I44: =C44*H44 -> 714 | J44: =I44-F44 -> 136.35
A45: MOTILAL OS NASDAQ100 ETF | B45: INF247L01AP4 | C45: 2 | D45: 45887 | E45: 205.47 | F45: 410.94 | G45: =TODAY() -> 46048 | H45: =IFERROR(__xludf.DUMMYFUNCTION("GOOGLEFINANCE(""MON100"")"),238.0) -> 238 | I45: =C45*H45 -> 476 | J45: =I45-F45 -> 65.06
A46: MOTILAL OS NASDAQ100 ETF | B46: INF247L01AP5 | C46: 2 | D46: 45947 | E46: 234.62 | F46: 469.24 | G46: =TODAY() -> 46048 | H46: =IFERROR(__xludf.DUMMYFUNCTION("GOOGLEFINANCE(""MON100"")"),238.0) -> 238 | I46: =C46*H46 -> 476 | J46: =I46-F46 -> 6.76
...

Sheet Crypto Analysis
A1: Schedule VDA Report And Capital Gains Transaction
A2: SI no | B2: Particulars / Aseset | C2: Price | D2: Quantity | E2: Date of acquisition/Purchase | F2: Date of transfer / Sold | G2: Head of income | H2: Cost of acquisition(round off) / Purchase Value * | I2: Consideration received (round off) / Sale Value | J2: Income from VDA / Gain or losses
A3: 1 | B3: BTC | C3: =H3/D3 -> 3206666.7 | D3: 0.00015 | E3: 44677 | F3: 45352 | G3: Capital Gains | H3: 481 | I3: 798 | J3: =-(H3-I3) -> 317
A4: 2 | B4: ETH | C4: =H4/D4 -> 237619.05 | D4: 0.0021 | E4: 44677 | F4: 45352 | G4: Capital Gains | H4: 499 | I4: 612 | J4: =-(H4-I4) -> 113
A5: 3 | B5: BTC | C5: =H5/D5 -> 2410000 | D5: 0.0001 | E5: 44722 | F5: 45352 | G5: Capital Gains | H5: 241 | I5: 532 | J5: =-(H5-I5) -> 291
A6: 4 | B6: ETH | C6: =H6/D6 -> 142173.91 | D6: 0.0023 | E6: 44722 | F6: 45352 | G6: Capital Gains | H6: 327 | I6: 670 | J6: =-(H6-I6) -> 343
A7: 5 | B7: WRX | C7: =H7/D7 -> 19.694054 | D7: 10.866224 | E7: 44722 | F7: 45352 | G7: Capital Gains | H7: 214 | I7: 247 | J7: =-(H7-I7) -> 33
A8: 6 | B8: BTC | C8: =H8/D8 -> 1753846.2 | D8: 0.00013 | E8: 44736 | F8: 45352 | G8: Capital Gains | H8: 228 | I8: 692 | J8: =-(H8-I8) -> 464
A9: 7 | B9: ETH | C9: =H9/D9 -> 95555.556 | D9: 0.0018 | E9: 44736 | F9: 45352 | G9: Capital Gains | H9: 172 | I9: 524 | J9: =-(H9-I9) -> 352
A10: 8 | B10: WRX | C10: =H10/D10 -> 19.215249 | D10: 0.364294 | E10: 44740 | F10: 45352 | G10: Capital Gains | H10: 7 | I10: 9 | J10: =-(H10-I10) -> 2
A11: 9 | B11: BTC | C11: =H11/D11 -> 1766666.7 | D11: 0.00033 | E11: 44750 | F11: 45352 | G11: Capital Gains | H11: 583 | I11: 1755 | J11: =-(H11-I11) -> 1172
A12: 10 | B12: ETH | C12: =H12/D12 -> 99821.429 | D12: 0.0056 | E12: 44750 | F12: 45352 | G12: Capital Gains | H12: 559 | I12: 1630 | J12: =-(H12-I12) -> 1071
A13: 11 | B13: WRX | C13: =H13/D13 -> 18.401761 | D13: 0.869482 | E13: 44750 | F13: 45352 | G13: Capital Gains | H13: 16 | I13: 20 | J13: =-(H13-I13) -> 4
A14: 12 | B14: BTC | C14: 5319182 | D14: 0.001 | E14: 45481
A15: 13 | B15: ETH | C15: 283900 | D15: 0.0163 | E15: 45481
A17: * Note: Cost of acquisition / Purchase Value excludes brokerage and other fees.
A18: Brokerage fee | B18: ₹48.31
A19: TDS Deducted | B19: ₹74.48
B21: Current Price | C21: Invested value | D21: Current value | E21: Return
A22: BTC | B22: =IFERROR(__xludf.DUMMYFUNCTION("GOOGLEFINANCE(""BTCINR"")"),8105255.146) -> 8105255.1 | C22: =C14*D14 -> 5319.182 | D22: =B22*D14 -> 8105.2551 | E22: =(D22-C22)*100/C22 -> 52.37785 | F22: INVESTED | G22: =SUMPRODUCT(C14:C15,D14:D15) -> 9946.752
A23: ETH | B23: =IFERROR(__xludf.DUMMYFUNCTION("GOOGLEFINANCE(""ETHINR"")"),268960.1667) -> 268960.17 | C23: =C15*D15 -> 4627.57 | D23: =B23*D15 -> 4384.0507 | E23: =(D23-C23)*100/C23 -> -5.2623576 | F23: Portfolio Value | G23: =SUMPRODUCT(D14:D15,B22:B23) -> 12489.306
F24: Returns | G24: =G23-G22 -> 2542.5539
G25: =G24/G22 -> 0.25561649

Sheet Stocks + ETF holdings
A1: Open Positions | J1: Days | S1: CAGR Calculation
A2: S. No. | B2: Stock | C2: Buy Date | D2: Buy Price | E2: Qty | F2: Buy Value | G2: CMP | H2: Current Value | I2: % Gain | J2: =TODAY() -> 46048 | K2: Strategy Name | L2: Target Price | M2: Total Potential Gain | N2: Remaining Gain | O2: Target Value | P2: 1 Year Return | S2: Date | T2: Amount
A3: 1 | B3: MUTHOOTCAP | C3: 44292 | D3: 374 | E3: 327 | F3: =D3*E3 -> 122298 | G3: =IFERROR(__xludf.DUMMYFUNCTION("GOOGLEFINANCE(""NSE:"" &B3, ""PRICE"")"),224.2) -> 224.2 | H3: =E3*G3 -> 73313.4 | I3: =(G3-D3)/D3 -> -0.40053476 | J3: =$J$2-C3 -> 1756 | K3: RH&S | L3: 503 | M3: =(L3-D3)/D3 -> 0.34491979 | N3: =(L3-G3)/G3 -> 1.2435326 | O3: =E3*L3 -> 164481 | P3: =IFERROR(__xludf.DUMMYFUNCTION("SPARKLINE(GOOGLEFINANCE(B3,""price"",today()-365,today()))"),"") | S3: 44105 | T3: -300000 | U3: Investment
A4: 2 | B4: HDFCBANK | C4: 44293 | D4: 2495 | E4: 44 | F4: =D4*E4 -> 109780 | G4: =IFERROR(__xludf.DUMMYFUNCTION("GOOGLEFINANCE(""NSE:"" &B4, ""PRICE"")"),915.8) -> 915.8 | H4: =E4*G4 -> 40295.2 | I4: =(G4-D4)/D4 -> -0.63294589 | J4: =$J$2-C4 -> 1755 | K4: RH&S | L4: =D4*1.4 -> 3493 | M4: =(L4-D4)/D4 -> 0.4 | N4: =(L4-G4)/G4 -> 2.8141516 | O4: =E4*L4 -> 153692 | P4: =IFERROR(__xludf.DUMMYFUNCTION("SPARKLINE(GOOGLEFINANCE(B4,""price"",today()-365,today()))"),"") | S4: 44136 | T4: -200000 | U4: Investment
A5: 3 | B5: AARTIDRUGS | C5: 44294 | D5: 712 | E5: 234 | F5: =D5*E5 -> 166608 | G5: =IFERROR(__xludf.DUMMYFUNCTION("GOOGLEFINANCE(""NSE:"" &B5, ""PRICE"")"),370.05) -> 370.05 | H5: =E5*G5 -> 86591.7 | I5: =(G5-D5)/D5 -> -0.48026685 | J5: =$J$2-C5 -> 1754 | K5: RH&S | L5: =D5*1.4 -> 996.8 | M5: =(L5-D5)/D5 -> 0.4 | N5: =(L5-G5)/G5 -> 1.69369 | O5: =E5*L5 -> 233251.2 | P5: =IFERROR(__xludf.DUMMYFUNCTION("SPARKLINE(GOOGLEFINANCE(B5,""price"",today()-365,today()))"),"") | S5: 44166 | T5: -100000 | U5: Investment
A6: 4 | B6: HEROMOTOCO | C6: 44313 | D6: 2903 | E6: 41 | F6: =D6*E6 -> 119023 | G6: =IFERROR(__xludf.DUMMYFUNCTION("GOOGLEFINANCE(""NSE:"" &B6, ""PRICE"")"),5388.0) -> 5388 | H6: =E6*G6 -> 220908 | I6: =(G6-D6)/D6 -> 0.85601102 | J6: =$J$2-C6 -> 1735 | K6: RH&S | L6: =D6*1.4 -> 4064.2 | M6: =(L6-D6)/D6 -> 0.4 | N6: =(L6-G6)/G6 -> -0.24569414 | O6: =E6*L6 -> 166632.2 | P6: =IFERROR(__xludf.DUMMYFUNCTION("SPARKLINE(GOOGLEFINANCE(B6,""price"",today()-365,today()))"),"") | S6: 44313 | T6: -108000 | U6: Investment
A7: 5 | B7: ARE&M | C7: 44314 | D7: 814 | E7: 149 | F7: =D7*E7 -> 121286 | G7: =IFERROR(__xludf.DUMMYFUNCTION("GOOGLEFINANCE(""NSE:"" &B7, ""PRICE"")"),826.85) -> 826.85 | H7: =E7*G7 -> 123200.65 | I7: =(G7-D7)/D7 -> 0.015786241 | J7: =$J$2-C7 -> 1734 | K7: RH&S | L7: =D7*1.4 -> 1139.6 | M7: =(L7-D7)/D7 -> 0.4 | N7: =(L7-G7)/G7 -> 0.37824273 | O7: =E7*L7 -> 169800.4 | P7: =IFERROR(__xludf.DUMMYFUNCTION("SPARKLINE(GOOGLEFINANCE(B7,""price"",today()-365,today()))"),"")
A8: 6 | B8: WHIRLPOOL | C8: 44315 | D8: 2171 | E8: 51 | F8: =D8*E8 -> 110721 | G8: =IFERROR(__xludf.DUMMYFUNCTION("GOOGLEFINANCE(""NSE:"" &B8, ""PRICE"")"),796.15) -> 796.15 | H8: =E8*G8 -> 40603.65 | I8: =(G8-D8)/D8 -> -0.63327959 | J8: =$J$2-C8 -> 1733 | K8: CWH | L8: =D8*1.4 -> 3039.4 | M8: =(L8-D8)/D8 -> 0.4 | N8: =(L8-G8)/G8 -> 2.8176223 | O8: =E8*L8 -> 155009.4 | P8: =IFERROR(__xludf.DUMMYFUNCTION("SPARKLINE(GOOGLEFINANCE(B8,""price"",today()-365,today()))"),"") | R8: Net Value as on | S8: =today() -> 46048 | T8: =H13 -> 2285057
A9: 7 | B9: MOTILALOFS | C9: 44316 | D9: 657 | E9: 176 | F9: =D9*E9 -> 115632 | G9: =IFERROR(__xludf.DUMMYFUNCTION("GOOGLEFINANCE(""NSE:"" &B9, ""PRICE"")"),749.4) -> 749.4 | H9: =E9*G9 -> 131894.4 | I9: =(G9-D9)/D9 -> 0.14063927 | J9: =$J$2-C9 -> 1732 | K9: CWH | L9: =D9*1.4 -> 919.8 | M9: =(L9-D9)/D9 -> 0.4 | N9: =(L9-G9)/G9 -> 0.22738191 | O9: =E9*L9 -> 161884.8 | P9: =IFERROR(__xludf.DUMMYFUNCTION("SPARKLINE(GOOGLEFINANCE(B9,""price"",today()-365,today()))"),"")
A10: 8 | B10: EICHERMOT | C10: 44321 | D10: 535 | E10: 225 | F10: =D10*E10 -> 120375 | G10: =IFERROR(__xludf.DUMMYFUNCTION("GOOGLEFINANCE(""NSE:"" &B10, ""PRICE"")"),6970.0) -> 6970 | H10: =E10*G10 -> 1568250 | I10: =(G10-D10)/D10 -> 12.028037 | J10: =$J$2-C10 -> 1727 | K10: CWH | L10: =D10*1.4 -> 749 | M10: =(L10-D10)/D10 -> 0.4 | N10: =(L10-G10)/G10 -> -0.89253945 | O10: =E10*L10 -> 168525 | P10: =IFERROR(__xludf.DUMMYFUNCTION("SPARKLINE(GOOGLEFINANCE(B10,""price"",today()-365,today()))"),"") | S10: Investment | T10: =-sum(T3:T7) -> 708000
A11: 9 | B11: COLPAL | C11: 44426 | D11: 1300 | E11: 100 | F11: =D11*E11 -> 130000 | G11: =IFERROR(__xludf.DUMMYFUNCTION("GOOGLEFINANCE(""NSE:"" &B11, ""PRICE"")"),2158.0) -> 2158 | H11: =E11*G11 -> 215800 | I11: =(G11-D11)/D11 -> 0.66 | J11: =$J$2-C11 -> 1622 | K11: CWH | L11: =D11*1.4 -> 1820 | M11: =(L11-D11)/D11 -> 0.4 | N11: =(L11-G11)/G11 -> -0.15662651 | O11: =E11*L11 -> 182000 | P11: =IFERROR(__xludf.DUMMYFUNCTION("SPARKLINE(GOOGLEFINANCE(B11,""price"",today()-365,today()))"),"") | S11: Profit | T11: =T8-T10 -> 1577057 | U11: =T11/T10 -> 2.2274816
B13: Total | F13: =sum(F3:F10) -> 985723 | H13: =sum(H3:H10) -> 2285057 | O13: =sum(O3:O12) -> 1555276 | S13: CAGR | T13: =xirr(T3:T8,S3:S8) -> 0.2531194
F14: Unrealised Gain | H14: =H13-F13 -> 1299334 | I14: =H14/H13 -> 0.56862214
A16: Closed Positions
A17: S. No. | B17: Stock | C17: Buy Date | D17: Buy Rate | E17: Qty | F17: Buy Value | G17: Sell Date | H17: Sell Price | I17: Sell Value | J17: Gain | K17: Days | L17: % Gain | M17: % Annual Gain | N17: 1 Year Return
A18: 1 | B18: KOTAKBANK | C18: 44111 | D18: 1343 | E18: 74 | F18: =D18*E18 -> 99382 | G18: 44139 | H18: 1630 | I18: =E18*H18 -> 120620 | J18: =I18-F18 -> 21238 | K18: =G18-C18 -> 28 | L18: =J18/F18 -> 0.21370067 | M18: =L18/K18*365 -> 2.7857409 | N18: =IFERROR(__xludf.DUMMYFUNCTION("SPARKLINE(GOOGLEFINANCE(B18,""price"",today()-365,today()))"),"")
A19: 2 | B19: AkzoINDIA | C19: 44141 | D19: 1935 | E19: 52 | F19: =D19*E19 -> 100620 | G19: 44196 | H19: 2415 | I19: =E19*H19 -> 125580 | J19: =I19-F19 -> 24960 | K19: =G19-C19 -> 55 | L19: =J19/F19 -> 0.24806202 | M19: =L19/K19*365 -> 1.6462297 | N19: =IFERROR(__xludf.DUMMYFUNCTION("SPARKLINE(GOOGLEFINANCE(B19,""price"",today()-365,today()))"),"")
A20: 3 | B20: BajajHldng | C20: 44154 | D20: 2878 | E20: 35 | F20: =D20*E20 -> 100730 | G20: 44252 | H20: 3740 | I20: =E20*H20 -> 130900 | J20: =I20-F20 -> 30170 | K20: =G20-C20 -> 98 | L20: =J20/F20 -> 0.29951355 | M20: =L20/K20*365 -> 1.1155352 | N20: =IFERROR(__xludf.DUMMYFUNCTION("SPARKLINE(GOOGLEFINANCE(B20,""price"",today()-365,today()))"),"")
A21: 4 | B21: BajajFinsv | C21: 44105 | D21: 6007 | E21: 17 | F21: =D21*E21 -> 102119 | G21: 44158 | H21: 8760 | I21: =E21*H21 -> 148920 | J21: =I21-F21 -> 46801 | K21: =G21-C21 -> 53 | L21: =J21/F21 -> 0.45829865 | M21: =L21/K21*365 -> 3.1562077 | N21: =IFERROR(__xludf.DUMMYFUNCTION("SPARKLINE(GOOGLEFINANCE(B21,""price"",today()-365,today()))"),"")
A22: 5 | B22: ICICIGI | C22: 44153 | D22: 1310 | E22: 76 | F22: =D22*E22 -> 99560 | G22: 44161 | H22: 1440 | I22: =E22*H22 -> 109440 | J22: =I22-F22 -> 9880 | K22: =G22-C22 -> 8 | L22: =J22/F22 -> 0.099236641 | M22: =L22/K22*365 -> 4.5276718 | N22: =IFERROR(__xludf.DUMMYFUNCTION("SPARKLINE(GOOGLEFINANCE(B22,""price"",today()-365,today()))"),"")
A23: 6 | B23: Page | C23: 44167 | D23: 23150 | E23: 4 | F23: =D23*E23 -> 92600 | G23: 44186 | H23: 28000 | I23: =E23*H23 -> 112000 | J23: =I23-F23 -> 19400 | K23: =G23-C23 -> 19 | L23: =J23/F23 -> 0.20950324 | M23: =L23/K23*365 -> 4.0246675 | N23: =IFERROR(__xludf.DUMMYFUNCTION("SPARKLINE(GOOGLEFINANCE(B23,""price"",today()-365,today()))"),"")
A24: 7 | B24: Symphony | C24: 44168 | D24: 865 | E24: 116 | F24: =D24*E24 -> 100340 | G24: 44208 | H24: 1090 | I24: =E24*H24 -> 126440 | J24: =I24-F24 -> 26100 | K24: =G24-C24 -> 40 | L24: =J24/F24 -> 0.26011561 | M24: =L24/K24*365 -> 2.3735549 | N24: =IFERROR(__xludf.DUMMYFUNCTION("SPARKLINE(GOOGLEFINANCE(B24,""price"",today()-365,today()))"),"")
A25: 8 | B25: Tastybite | C25: 44186 | D25: 11750 | E25: 9 | F25: =D25*E25 -> 105750 | G25: 44231 | H25: 13100 | I25: =E25*H25 -> 117900 | J25: =I25-F25 -> 12150 | K25: =G25-C25 -> 45 | L25: =J25/F25 -> 0.11489362 | M25: =L25/K25*365 -> 0.93191489 | N25: =IFERROR(__xludf.DUMMYFUNCTION("SPARKLINE(GOOGLEFINANCE(B25,""price"",today()-365,today()))"),"")
A26: 9 | B26: JCHAC | C26: 44187 | D26: 2150 | E26: 47 | F26: =D26*E26 -> 101050 | G26: 44193 | H26: 2600 | I26: =E26*H26 -> 122200 | J26: =I26-F26 -> 21150 | K26: =G26-C26 -> 6 | L26: =J26/F26 -> 0.20930233 | M26: =L26/K26*365 -> 12.732558 | N26: =IFERROR(__xludf.DUMMYFUNCTION("SPARKLINE(GOOGLEFINANCE(B26,""price"",today()-365,today()))"),"#N/A") -> #N/A
A27: 10 | B27: PGHH | C27: 44194 | D27: 11000 | E27: 9 | F27: =D27*E27 -> 99000 | G27: 44231 | H27: 12200 | I27: =E27*H27 -> 109800 | J27: =I27-F27 -> 10800 | K27: =G27-C27 -> 37 | L27: =J27/F27 -> 0.10909091 | M27: =L27/K27*365 -> 1.0761671 | N27: =IFERROR(__xludf.DUMMYFUNCTION("SPARKLINE(GOOGLEFINANCE(B27,""price"",today()-365,today()))"),"")
A28: 11 | B28: CentralBK | C28: 44202 | D28: 14.2 | E28: 7042 | F28: =D28*E28 -> 99996.4 | G28: 44245 | H28: 23.7 | I28: =E28*H28 -> 166895.4 | J28: =I28-F28 -> 66899 | K28: =G28-C28 -> 43 | L28: =J28/F28 -> 0.66901408 | M28: =L28/K28*365 -> 5.6788405 | N28: =IFERROR(__xludf.DUMMYFUNCTION("SPARKLINE(GOOGLEFINANCE(B28,""price"",today()-365,today()))"),"")
A29: 12 | B29: Bata | C29: 44153 | D29: 1370 | E29: 73 | F29: =D29*E29 -> 100010 | G29: 44204 | H29: 1645 | I29: =E29*H29 -> 120085 | J29: =I29-F29 -> 20075 | K29: =G29-C29 -> 51 | L29: =J29/F29 -> 0.20072993 | M29: =L29/K29*365 -> 1.4365965 | N29: =IFERROR(__xludf.DUMMYFUNCTION("SPARKLINE(GOOGLEFINANCE(B29,""price"",today()-365,today()))"),"")
A30: 13 | B30: GMMPFAUDLR | C30: 44244 | D30: 3903 | E30: 26 | F30: =D30*E30 -> 101478 | G30: 44246 | H30: 4660 | I30: =E30*H30 -> 121160 | J30: =I30-F30 -> 19682 | K30: =G30-C30 -> 2 | L30: =J30/F30 -> 0.19395337 | M30: =L30/K30*365 -> 35.39649 | N30: =IFERROR(__xludf.DUMMYFUNCTION("SPARKLINE(GOOGLEFINANCE(B30,""price"",today()-365,today()))"),"")
A31: 14 | B31: HINDUNILVR | C31: 44153 | D31: 2164 | E31: 46 | F31: =D31*E31 -> 99544 | G31: 44292 | H31: 2400 | I31: =E31*H31 -> 110400 | J31: =I31-F31 -> 10856 | K31: =G31-C31 -> 139 | L31: =J31/F31 -> 0.1090573 | M31: =L31/K31*365 -> 0.28637349 | N31: =IFERROR(__xludf.DUMMYFUNCTION("SPARKLINE(GOOGLEFINANCE(B31,""price"",today()-365,today()))"),"")
A32: 15 | B32: ISEC | C32: 44237 | D32: 414 | E32: 242 | F32: =D32*E32 -> 100188 | G32: 44313 | H32: 478 | I32: =E32*H32 -> 115676 | J32: =I32-F32 -> 15488 | K32: =G32-C32 -> 76 | L32: =J32/F32 -> 0.15458937 | M32: =L32/K32*365 -> 0.7424358 | N32: =IFERROR(__xludf.DUMMYFUNCTION("SPARKLINE(GOOGLEFINANCE(B32,""price"",today()-365,today()))"),"")
A33: 16 | B33: FINEORG | C33: 44189 | D33: 2410 | E33: 41 | F33: =D33*E33 -> 98810 | G33: 44315 | H33: 2930 | I33: =E33*H33 -> 120130 | J33: =I33-F33 -> 21320 | K33: =G33-C33 -> 126 | L33: =J33/F33 -> 0.21576763 | M33: =L33/K33*365 -> 0.62504116 | N33: =IFERROR(__xludf.DUMMYFUNCTION("SPARKLINE(GOOGLEFINANCE(B33,""price"",today()-365,today()))"),"")
A34: 17 | B34: VENKEYS | C34: 44252 | D34: 1604 | E34: 62 | F34: =D34*E34 -> 99448 | G34: 44328 | H34: 1922 | I34: =E34*H34 -> 119164 | J34: =I34-F34 -> 19716 | K34: =G34-C34 -> 76 | L34: =J34/F34 -> 0.19825436 | M34: =L34/K34*365 -> 0.95214267 | N34: =IFERROR(__xludf.DUMMYFUNCTION("SPARKLINE(GOOGLEFINANCE(B34,""price"",today()-365,today()))"),"")
H36: Realised Gain | J36: =sum(J18:J34) -> 396685
